Traceback (most recent call last):
  File "F:\PyCharm\MathDiskret\.venv\Lib\site-packages\jupyter_cache\executors\utils.py", line 58, in single_nb_execution
    executenb(
  File "F:\PyCharm\MathDiskret\.venv\Lib\site-packages\nbclient\client.py", line 1314, in execute
    return NotebookClient(nb=nb, resources=resources, km=km, **kwargs).execute()
           ^^^^^^^^^^^^^^^^^^^^^^^^^^^^^^^^^^^^^^^^^^^^^^^^^^^^^^^^^^^^^^^^^^^^^
  File "F:\PyCharm\MathDiskret\.venv\Lib\site-packages\jupyter_core\utils\__init__.py", line 165, in wrapped
    return loop.run_until_complete(inner)
           ^^^^^^^^^^^^^^^^^^^^^^^^^^^^^^
  File "C:\Program Files\WindowsApps\PythonSoftwareFoundation.Python.3.12_3.12.2032.0_x64__qbz5n2kfra8p0\Lib\asyncio\base_events.py", line 687, in run_until_complete
    return future.result()
           ^^^^^^^^^^^^^^^
  File "F:\PyCharm\MathDiskret\.venv\Lib\site-packages\nbclient\client.py", line 709, in async_execute
    await self.async_execute_cell(
  File "F:\PyCharm\MathDiskret\.venv\Lib\site-packages\nbclient\client.py", line 1062, in async_execute_cell
    await self._check_raise_for_error(cell, cell_index, exec_reply)
  File "F:\PyCharm\MathDiskret\.venv\Lib\site-packages\nbclient\client.py", line 918, in _check_raise_for_error
    raise CellExecutionError.from_cell_and_msg(cell, exec_reply_content)
nbclient.exceptions.CellExecutionError: An error occurred while executing the following cell:
------------------
import networkx as nx
import matplotlib.pyplot as plt

# G = nx.Graph([(0, 1), (0, 2), (0, 3), (1, 2), (1, 3)])

g = nx.Graph()

g.nodes()

g.add_edge(9, 7)
g.add_edge(7, 5)
g.add_edge(7, 8)
g.add_edge(7, 6)
g.add_edge(8, 5)
g.add_edge(8, 6)
g.add_edge(6, 5)
g.add_edge(6, 4)
g.add_edge(5, 4)
g.add_edge(4, 3)
g.add_edge(4, 1)
g.add_edge(3, 1)
g.add_edge(2, 3)
g.add_edge(2, 1)

# nx.draw(g)
nx.draw(g, with_labels = True)

print("Degree centrality: \n", nx.degree_centrality(g))
print("Closeness centrality: \n", nx.closeness_centrality(g))
print("Beetweeness centrality: \n", nx.betweenness_centrality(g))
# plt.savefig("filename.png")
plt.show()

------------------


[1;31m---------------------------------------------------------------------------[0m
[1;31mModuleNotFoundError[0m                       Traceback (most recent call last)
Cell [1;32mIn[1], line 2[0m
[0;32m      1[0m [38;5;28;01mimport[39;00m [38;5;21;01mnetworkx[39;00m [38;5;28;01mas[39;00m [38;5;21;01mnx[39;00m
[1;32m----> 2[0m [38;5;28;01mimport[39;00m [38;5;21;01mmatplotlib[39;00m[38;5;21;01m.[39;00m[38;5;21;01mpyplot[39;00m [38;5;28;01mas[39;00m [38;5;21;01mplt[39;00m
[0;32m      4[0m [38;5;66;03m# G = nx.Graph([(0, 1), (0, 2), (0, 3), (1, 2), (1, 3)])[39;00m
[0;32m      6[0m g [38;5;241m=[39m nx[38;5;241m.[39mGraph()

[1;31mModuleNotFoundError[0m: No module named 'matplotlib'

